Workbook

Sheet Dashboard
A1: HR Analytics Dashboard
A2: Sample data only. Attrition rate = exits / (active + exits).
A4: Active headcount | B4: =COUNTIF(Data!$E$2:$E$141,"Active") -> 119
A5: Exits | B5: =COUNTIF(Data!$E$2:$E$141,"Exited") -> 21
A6: Attrition rate | B6: =IFERROR(B5/(B4+B5),0) -> 0.15
A9: Department | B9: Active | C9: Exited | D9: Attrition %
A10: Sales | B10: =COUNTIFS(Data!$B$2:$B$141,A10,Data!$E$2:$E$141,"Active") -> 46 | C10: =COUNTIFS(Data!$B$2:$B$141,A10,Data!$E$2:$E$141,"Exited") -> 9 | D10: =IFERROR(C10/(B10+C10),0) -> 0.16363636
A11: Engineering | B11: =COUNTIFS(Data!$B$2:$B$141,A11,Data!$E$2:$E$141,"Active") -> 33 | C11: =COUNTIFS(Data!$B$2:$B$141,A11,Data!$E$2:$E$141,"Exited") -> 6 | D11: =IFERROR(C11/(B11+C11),0) -> 0.15384615
A12: HR | B12: =COUNTIFS(Data!$B$2:$B$141,A12,Data!$E$2:$E$141,"Active") -> 13 | C12: =COUNTIFS(Data!$B$2:$B$141,A12,Data!$E$2:$E$141,"Exited") -> 1 | D12: =IFERROR(C12/(B12+C12),0) -> 0.071428571
A13: Finance | B13: =COUNTIFS(Data!$B$2:$B$141,A13,Data!$E$2:$E$141,"Active") -> 10 | C13: =COUNTIFS(Data!$B$2:$B$141,A13,Data!$E$2:$E$141,"Exited") -> 0 | D13: =IFERROR(C13/(B13+C13),0) -> 0
A14: Operations | B14: =COUNTIFS(Data!$B$2:$B$141,A14,Data!$E$2:$E$141,"Active") -> 17 | C14: =COUNTIFS(Data!$B$2:$B$141,A14,Data!$E$2:$E$141,"Exited") -> 5 | D14: =IFERROR(C14/(B14+C14),0) -> 0.22727273
A17: Month (2025) | B17: Joiners
A18: 2025-01 | B18: =COUNTIF(Data!$F$2:$F$141,A18) -> 3
A19: 2025-02 | B19: =COUNTIF(Data!$F$2:$F$141,A19) -> 2
A20: 2025-03 | B20: =COUNTIF(Data!$F$2:$F$141,A20) -> 6
A21: 2025-04 | B21: =COUNTIF(Data!$F$2:$F$141,A21) -> 3
A22: 2025-05 | B22: =COUNTIF(Data!$F$2:$F$141,A22) -> 2
A23: 2025-06 | B23: =COUNTIF(Data!$F$2:$F$141,A23) -> 1
A24: 2025-07 | B24: =COUNTIF(Data!$F$2:$F$141,A24) -> 7
A25: 2025-08 | B25: =COUNTIF(Data!$F$2:$F$141,A25) -> 5
A26: 2025-09 | B26: =COUNTIF(Data!$F$2:$F$141,A26) -> 6
A27: 2025-10 | B27: =COUNTIF(Data!$F$2:$F$141,A27) -> 8
A28: 2025-11 | B28: =COUNTIF(Data!$F$2:$F$141,A28) -> 8
A29: 2025-12 | B29: =COUNTIF(Data!$F$2:$F$141,A29) -> 5

Sheet Data
A1: Employee ID | B1: Department | C1: Join Date | D1: Exit Date | E1: Status (auto) | F1: Join Month (auto) | H1: Sample data only: randomly generated, not real employees. Blue = edit. Add rows and extend the ranges on the Dashboard.
A2: E-001 | B2: Sales | C2: 45889 | E2: =IF(D2="","Active","Exited") -> Active | F2: =TEXT(C2,"yyyy-mm") -> 2025-08
A3: E-002 | B3: Engineering | C3: 44930 | E3: =IF(D3="","Active","Exited") -> Active | F3: =TEXT(C3,"yyyy-mm") -> 2023-01
A4: E-003 | B4: HR | C4: 45100 | E4: =IF(D4="","Active","Exited") -> Active | F4: =TEXT(C4,"yyyy-mm") -> 2023-06
A5: E-004 | B5: Sales | C5: 45722 | E5: =IF(D5="","Active","Exited") -> Active | F5: =TEXT(C5,"yyyy-mm") -> 2025-03
A6: E-005 | B6: Finance | C6: 45906 | E6: =IF(D6="","Active","Exited") -> Active | F6: =TEXT(C6,"yyyy-mm") -> 2025-09
A7: E-006 | B7: Engineering | C7: 45607 | E7: =IF(D7="","Active","Exited") -> Active | F7: =TEXT(C7,"yyyy-mm") -> 2024-11
A8: E-007 | B8: Engineering | C8: 45749 | E8: =IF(D8="","Active","Exited") -> Active | F8: =TEXT(C8,"yyyy-mm") -> 2025-04
A9: E-008 | B9: Sales | C9: 45252 | D9: 45377 | E9: =IF(D9="","Active","Exited") -> Exited | F9: =TEXT(C9,"yyyy-mm") -> 2023-11
A10: E-009 | B10: Sales | C10: 45880 | E10: =IF(D10="","Active","Exited") -> Active | F10: =TEXT(C10,"yyyy-mm") -> 2025-08
A11: E-010 | B11: Sales | C11: 45898 | E11: =IF(D11="","Active","Exited") -> Active | F11: =TEXT(C11,"yyyy-mm") -> 2025-08
A12: E-011 | B12: Engineering | C12: 45195 | D12: 45664 | E12: =IF(D12="","Active","Exited") -> Exited | F12: =TEXT(C12,"yyyy-mm") -> 2023-09
A13: E-012 | B13: Operations | C13: 45137 | E13: =IF(D13="","Active","Exited") -> Active | F13: =TEXT(C13,"yyyy-mm") -> 2023-07
A14: E-013 | B14: Operations | C14: 45815 | E14: =IF(D14="","Active","Exited") -> Active | F14: =TEXT(C14,"yyyy-mm") -> 2025-06
A15: E-014 | B15: Sales | C15: 45359 | D15: 45527 | E15: =IF(D15="","Active","Exited") -> Exited | F15: =TEXT(C15,"yyyy-mm") -> 2024-03
A16: E-015 | B16: Sales | C16: 45419 | E16: =IF(D16="","Active","Exited") -> Active | F16: =TEXT(C16,"yyyy-mm") -> 2024-05
A17: E-016 | B17: Engineering | C17: 45785 | E17: =IF(D17="","Active","Exited") -> Active | F17: =TEXT(C17,"yyyy-mm") -> 2025-05
A18: E-017 | B18: Sales | C18: 45651 | E18: =IF(D18="","Active","Exited") -> Active | F18: =TEXT(C18,"yyyy-mm") -> 2024-12
A19: E-018 | B19: HR | C19: 45985 | E19: =IF(D19="","Active","Exited") -> Active | F19: =TEXT(C19,"yyyy-mm") -> 2025-11
A20: E-019 | B20: Operations | C20: 45954 | E20: =IF(D20="","Active","Exited") -> Active | F20: =TEXT(C20,"yyyy-mm") -> 2025-10
A21: E-020 | B21: Engineering | C21: 44965 | E21: =IF(D21="","Active","Exited") -> Active | F21: =TEXT(C21,"yyyy-mm") -> 2023-02
A22: E-021 | B22: Finance | C22: 44935 | E22: =IF(D22="","Active","Exited") -> Active | F22: =TEXT(C22,"yyyy-mm") -> 2023-01
A23: E-022 | B23: Sales | C23: 45216 | E23: =IF(D23="","Active","Exited") -> Active | F23: =TEXT(C23,"yyyy-mm") -> 2023-10
A24: E-023 | B24: HR | C24: 45053 | E24: =IF(D24="","Active","Exited") -> Active | F24: =TEXT(C24,"yyyy-mm") -> 2023-05
A25: E-024 | B25: Engineering | C25: 45915 | E25: =IF(D25="","Active","Exited") -> Active | F25: =TEXT(C25,"yyyy-mm") -> 2025-09
A26: E-025 | B26: Sales | C26: 45043 | D26: 45244 | E26: =IF(D26="","Active","Exited") -> Exited | F26: =TEXT(C26,"yyyy-mm") -> 2023-04
A27: E-026 | B27: Sales | C27: 45127 | E27: =IF(D27="","Active","Exited") -> Active | F27: =TEXT(C27,"yyyy-mm") -> 2023-07
A28: E-027 | B28: Engineering | C28: 45056 | E28: =IF(D28="","Active","Exited") -> Active | F28: =TEXT(C28,"yyyy-mm") -> 2023-05
A29: E-028 | B29: Engineering | C29: 45962 | E29: =IF(D29="","Active","Exited") -> Active | F29: =TEXT(C29,"yyyy-mm") -> 2025-11
A30: E-029 | B30: Sales | C30: 45494 | E30: =IF(D30="","Active","Exited") -> Active | F30: =TEXT(C30,"yyyy-mm") -> 2024-07
A31: E-030 | B31: Engineering | C31: 45906 | E31: =IF(D31="","Active","Exited") -> Active | F31: =TEXT(C31,"yyyy-mm") -> 2025-09
A32: E-031 | B32: Sales | C32: 45998 | E32: =IF(D32="","Active","Exited") -> Active | F32: =TEXT(C32,"yyyy-mm") -> 2025-12
A33: E-032 | B33: Operations | C33: 45458 | E33: =IF(D33="","Active","Exited") -> Active | F33: =TEXT(C33,"yyyy-mm") -> 2024-06
A34: E-033 | B34: Operations | C34: 45341 | E34: =IF(D34="","Active","Exited") -> Active | F34: =TEXT(C34,"yyyy-mm") -> 2024-02
A35: E-034 | B35: Sales | C35: 45176 | E35: =IF(D35="","Active","Exited") -> Active | F35: =TEXT(C35,"yyyy-mm") -> 2023-09
A36: E-035 | B36: Engineering | C36: 45419 | E36: =IF(D36="","Active","Exited") -> Active | F36: =TEXT(C36,"yyyy-mm") -> 2024-05
A37: E-036 | B37: Sales | C37: 45547 | E37: =IF(D37="","Active","Exited") -> Active | F37: =TEXT(C37,"yyyy-mm") -> 2024-09
A38: E-037 | B38: Operations | C38: 45243 | E38: =IF(D38="","Active","Exited") -> Active | F38: =TEXT(C38,"yyyy-mm") -> 2023-11
A39: E-038 | B39: Engineering | C39: 45676 | D39: 45806 | E39: =IF(D39="","Active","Exited") -> Exited | F39: =TEXT(C39,"yyyy-mm") -> 2025-01
A40: E-039 | B40: Operations | C40: 45376 | E40: =IF(D40="","Active","Exited") -> Active | F40: =TEXT(C40,"yyyy-mm") -> 2024-03
...
